Watching for file changes with StatReloader
C:\Users\Aleksey L\Desktop\kuzler\kuzler\products\urls.py changed, reloading.
Watching for file changes with StatReloader
C:\Users\Aleksey L\Desktop\kuzler\kuzler\products\urls.py changed, reloading.
Watching for file changes with StatReloader
C:\Users\Aleksey L\Desktop\kuzler\kuzler\products\urls.py changed, reloading.
Watching for file changes with StatReloader
Not Found: /
"GET / HTTP/1.1" 404 2473
Not Found: /favicon.ico
"GET /favicon.ico HTTP/1.1" 404 2524
"GET /admin/ HTTP/1.1" 200 9910
Internal Server Error: /admin/products/product/
Traceback (most recent call last):
  File "C:\Users\Aleksey L\AppData\Local\Programs\Python\Python313\Lib\site-packages\django\db\backends\utils.py", line 105, in _execute
    return self.cursor.execute(sql, params)
           ~~~~~~~~~~~~~~~~~~~^^^^^^^^^^^^^
  File "C:\Users\Aleksey L\AppData\Local\Programs\Python\Python313\Lib\site-packages\django\db\backends\sqlite3\base.py", line 354, in execute
    return super().execute(query, params)
           ~~~~~~~~~~~~~~~^^^^^^^^^^^^^^^
sqlite3.OperationalError: no such column: products_product.nfc_id

The above exception was the direct cause of the following exception:

Traceback (most recent call last):
  File "C:\Users\Aleksey L\AppData\Local\Programs\Python\Python313\Lib\site-packages\django\core\handlers\exception.py", line 55, in inner
    response = get_response(request)
  File "C:\Users\Aleksey L\AppData\Local\Programs\Python\Python313\Lib\site-packages\django\core\handlers\base.py", line 197, in _get_response
    response = wrapped_callback(request, *callback_args, **callback_kwargs)
  File "C:\Users\Aleksey L\AppData\Local\Programs\Python\Python313\Lib\site-packages\django\contrib\admin\options.py", line 718, in wrapper
    return self.admin_site.admin_view(view)(*args, **kwargs)
           ~~~~~~~~~~~~~~~~~~~~~~~~~~~~~~~~^^^^^^^^^^^^^^^^^
  File "C:\Users\Aleksey L\AppData\Local\Programs\Python\Python313\Lib\site-packages\django\utils\decorators.py", line 188, in _view_wrapper
    result = _process_exception(request, e)
  File "C:\Users\Aleksey L\AppData\Local\Programs\Python\Python313\Lib\site-packages\django\utils\decorators.py", line 186, in _view_wrapper
    response = view_func(request, *args, **kwargs)
  File "C:\Users\Aleksey L\AppData\Local\Programs\Python\Python313\Lib\site-packages\django\views\decorators\cache.py", line 80, in _view_wrapper
    response = view_func(request, *args, **kwargs)
  File "C:\Users\Aleksey L\AppData\Local\Programs\Python\Python313\Lib\site-packages\django\contrib\admin\sites.py", line 241, in inner
    return view(request, *args, **kwargs)
  File "C:\Users\Aleksey L\AppData\Local\Programs\Python\Python313\Lib\site-packages\django\utils\decorators.py", line 48, in _wrapper
    return bound_method(*args, **kwargs)
  File "C:\Users\Aleksey L\AppData\Local\Programs\Python\Python313\Lib\site-packages\django\utils\decorators.py", line 188, in _view_wrapper
    result = _process_exception(request, e)
  File "C:\Users\Aleksey L\AppData\Local\Programs\Python\Python313\Lib\site-packages\django\utils\decorators.py", line 186, in _view_wrapper
    response = view_func(request, *args, **kwargs)
  File "C:\Users\Aleksey L\AppData\Local\Programs\Python\Python313\Lib\site-packages\django\contrib\admin\options.py", line 2140, in changelist_view
    "selection_note": _("0 of %(cnt)s selected") % {"cnt": len(cl.result_list)},
                                                           ~~~^^^^^^^^^^^^^^^^
  File "C:\Users\Aleksey L\AppData\Local\Programs\Python\Python313\Lib\site-packages\django\db\models\query.py", line 382, in __len__
    self._fetch_all()
    ~~~~~~~~~~~~~~~^^
  File "C:\Users\Aleksey L\AppData\Local\Programs\Python\Python313\Lib\site-packages\django\db\models\query.py", line 1928, in _fetch_all
    self._result_cache = list(self._iterable_class(self))
                         ~~~~^^^^^^^^^^^^^^^^^^^^^^^^^^^^
  File "C:\Users\Aleksey L\AppData\Local\Programs\Python\Python313\Lib\site-packages\django\db\models\query.py", line 91, in __iter__
    results = compiler.execute_sql(
        chunked_fetch=self.chunked_fetch, chunk_size=self.chunk_size
    )
  File "C:\Users\Aleksey L\AppData\Local\Programs\Python\Python313\Lib\site-packages\django\db\models\sql\compiler.py", line 1574, in execute_sql
    cursor.execute(sql, params)
    ~~~~~~~~~~~~~~^^^^^^^^^^^^^
  File "C:\Users\Aleksey L\AppData\Local\Programs\Python\Python313\Lib\site-packages\django\db\backends\utils.py", line 122, in execute
    return super().execute(sql, params)
           ~~~~~~~~~~~~~~~^^^^^^^^^^^^^
  File "C:\Users\Aleksey L\AppData\Local\Programs\Python\Python313\Lib\site-packages\django\db\backends\utils.py", line 79, in execute
    return self._execute_with_wrappers(
           ~~~~~~~~~~~~~~~~~~~~~~~~~~~^
        sql, params, many=False, executor=self._execute
        ^^^^^^^^^^^^^^^^^^^^^^^^^^^^^^^^^^^^^^^^^^^^^^^
    )
    ^
  File "C:\Users\Aleksey L\AppData\Local\Programs\Python\Python313\Lib\site-packages\django\db\backends\utils.py", line 92, in _execute_with_wrappers
    return executor(sql, params, many, context)
  File "C:\Users\Aleksey L\AppData\Local\Programs\Python\Python313\Lib\site-packages\django\db\backends\utils.py", line 100, in _execute
    with self.db.wrap_database_errors:
         ^^^^^^^^^^^^^^^^^^^^^^^^^^^^
  File "C:\Users\Aleksey L\AppData\Local\Programs\Python\Python313\Lib\site-packages\django\db\utils.py", line 91, in __exit__
    raise dj_exc_value.with_traceback(traceback) from exc_value
  File "C:\Users\Aleksey L\AppData\Local\Programs\Python\Python313\Lib\site-packages\django\db\backends\utils.py", line 105, in _execute
    return self.cursor.execute(sql, params)
           ~~~~~~~~~~~~~~~~~~~^^^^^^^^^^^^^
  File "C:\Users\Aleksey L\AppData\Local\Programs\Python\Python313\Lib\site-packages\django\db\backends\sqlite3\base.py", line 354, in execute
    return super().execute(query, params)
           ~~~~~~~~~~~~~~~^^^^^^^^^^^^^^^
django.db.utils.OperationalError: no such column: products_product.nfc_id
"GET /admin/products/product/ HTTP/1.1" 500 173562
"GET /admin/ HTTP/1.1" 200 9910
"GET /admin/products/nfctag/ HTTP/1.1" 500 440134
"GET /admin/ HTTP/1.1" 200 9910
Internal Server Error: /admin/authtoken/tokenproxy/
Traceback (most recent call last):
  File "C:\Users\Aleksey L\AppData\Local\Programs\Python\Python313\Lib\site-packages\django\db\backends\utils.py", line 105, in _execute
    return self.cursor.execute(sql, params)
           ~~~~~~~~~~~~~~~~~~~^^^^^^^^^^^^^
  File "C:\Users\Aleksey L\AppData\Local\Programs\Python\Python313\Lib\site-packages\django\db\backends\sqlite3\base.py", line 354, in execute
    return super().execute(query, params)
           ~~~~~~~~~~~~~~~^^^^^^^^^^^^^^^
sqlite3.OperationalError: no such table: authtoken_token

The above exception was the direct cause of the following exception:

Traceback (most recent call last):
  File "C:\Users\Aleksey L\AppData\Local\Programs\Python\Python313\Lib\site-packages\django\core\handlers\exception.py", line 55, in inner
    response = get_response(request)
  File "C:\Users\Aleksey L\AppData\Local\Programs\Python\Python313\Lib\site-packages\django\core\handlers\base.py", line 197, in _get_response
    response = wrapped_callback(request, *callback_args, **callback_kwargs)
  File "C:\Users\Aleksey L\AppData\Local\Programs\Python\Python313\Lib\site-packages\django\contrib\admin\options.py", line 718, in wrapper
    return self.admin_site.admin_view(view)(*args, **kwargs)
           ~~~~~~~~~~~~~~~~~~~~~~~~~~~~~~~~^^^^^^^^^^^^^^^^^
  File "C:\Users\Aleksey L\AppData\Local\Programs\Python\Python313\Lib\site-packages\django\utils\decorators.py", line 188, in _view_wrapper
    result = _process_exception(request, e)
  File "C:\Users\Aleksey L\AppData\Local\Programs\Python\Python313\Lib\site-packages\django\utils\decorators.py", line 186, in _view_wrapper
    response = view_func(request, *args, **kwargs)
  File "C:\Users\Aleksey L\AppData\Local\Programs\Python\Python313\Lib\site-packages\django\views\decorators\cache.py", line 80, in _view_wrapper
    response = view_func(request, *args, **kwargs)
  File "C:\Users\Aleksey L\AppData\Local\Programs\Python\Python313\Lib\site-packages\django\contrib\admin\sites.py", line 241, in inner
    return view(request, *args, **kwargs)
  File "C:\Users\Aleksey L\AppData\Local\Programs\Python\Python313\Lib\site-packages\django\utils\decorators.py", line 48, in _wrapper
    return bound_method(*args, **kwargs)
  File "C:\Users\Aleksey L\AppData\Local\Programs\Python\Python313\Lib\site-packages\django\utils\decorators.py", line 188, in _view_wrapper
    result = _process_exception(request, e)
  File "C:\Users\Aleksey L\AppData\Local\Programs\Python\Python313\Lib\site-packages\django\utils\decorators.py", line 186, in _view_wrapper
    response = view_func(request, *args, **kwargs)
  File "C:\Users\Aleksey L\AppData\Local\Programs\Python\Python313\Lib\site-packages\django\contrib\admin\options.py", line 2001, in changelist_view
    cl = self.get_changelist_instance(request)
  File "C:\Users\Aleksey L\AppData\Local\Programs\Python\Python313\Lib\site-packages\django\contrib\admin\options.py", line 866, in get_changelist_instance
    return ChangeList(
        request,
    ...<12 lines>...
        self.search_help_text,
    )
  File "C:\Users\Aleksey L\AppData\Local\Programs\Python\Python313\Lib\site-packages\django\contrib\admin\views\main.py", line 146, in __init__
    self.get_results(request)
    ~~~~~~~~~~~~~~~~^^^^^^^^^
  File "C:\Users\Aleksey L\AppData\Local\Programs\Python\Python313\Lib\site-packages\django\contrib\admin\views\main.py", line 313, in get_results
    result_count = paginator.count
                   ^^^^^^^^^^^^^^^
  File "C:\Users\Aleksey L\AppData\Local\Programs\Python\Python313\Lib\site-packages\django\utils\functional.py", line 47, in __get__
    res = instance.__dict__[self.name] = self.func(instance)
                                         ~~~~~~~~~^^^^^^^^^^
  File "C:\Users\Aleksey L\AppData\Local\Programs\Python\Python313\Lib\site-packages\django\core\paginator.py", line 110, in count
    return c()
  File "C:\Users\Aleksey L\AppData\Local\Programs\Python\Python313\Lib\site-packages\django\db\models\query.py", line 620, in count
    return self.query.get_count(using=self.db)
           ~~~~~~~~~~~~~~~~~~~~^^^^^^^^^^^^^^^
  File "C:\Users\Aleksey L\AppData\Local\Programs\Python\Python313\Lib\site-packages\django\db\models\sql\query.py", line 630, in get_count
    return obj.get_aggregation(using, {"__count": Count("*")})["__count"]
           ~~~~~~~~~~~~~~~~~~~^^^^^^^^^^^^^^^^^^^^^^^^^^^^^^^^
  File "C:\Users\Aleksey L\AppData\Local\Programs\Python\Python313\Lib\site-packages\django\db\models\sql\query.py", line 616, in get_aggregation
    result = compiler.execute_sql(SINGLE)
  File "C:\Users\Aleksey L\AppData\Local\Programs\Python\Python313\Lib\site-packages\django\db\models\sql\compiler.py", line 1574, in execute_sql
    cursor.execute(sql, params)
    ~~~~~~~~~~~~~~^^^^^^^^^^^^^
  File "C:\Users\Aleksey L\AppData\Local\Programs\Python\Python313\Lib\site-packages\django\db\backends\utils.py", line 122, in execute
    return super().execute(sql, params)
           ~~~~~~~~~~~~~~~^^^^^^^^^^^^^
  File "C:\Users\Aleksey L\AppData\Local\Programs\Python\Python313\Lib\site-packages\django\db\backends\utils.py", line 79, in execute
    return self._execute_with_wrappers(
           ~~~~~~~~~~~~~~~~~~~~~~~~~~~^
        sql, params, many=False, executor=self._execute
        ^^^^^^^^^^^^^^^^^^^^^^^^^^^^^^^^^^^^^^^^^^^^^^^
    )
    ^
  File "C:\Users\Aleksey L\AppData\Local\Programs\Python\Python313\Lib\site-packages\django\db\backends\utils.py", line 92, in _execute_with_wrappers
    return executor(sql, params, many, context)
  File "C:\Users\Aleksey L\AppData\Local\Programs\Python\Python313\Lib\site-packages\django\db\backends\utils.py", line 100, in _execute
    with self.db.wrap_database_errors:
         ^^^^^^^^^^^^^^^^^^^^^^^^^^^^
  File "C:\Users\Aleksey L\AppData\Local\Programs\Python\Python313\Lib\site-packages\django\db\utils.py", line 91, in __exit__
    raise dj_exc_value.with_traceback(traceback) from exc_value
  File "C:\Users\Aleksey L\AppData\Local\Programs\Python\Python313\Lib\site-packages\django\db\backends\utils.py", line 105, in _execute
    return self.cursor.execute(sql, params)
           ~~~~~~~~~~~~~~~~~~~^^^^^^^^^^^^^
  File "C:\Users\Aleksey L\AppData\Local\Programs\Python\Python313\Lib\site-packages\django\db\backends\sqlite3\base.py", line 354, in execute
    return super().execute(query, params)
           ~~~~~~~~~~~~~~~^^^^^^^^^^^^^^^
django.db.utils.OperationalError: no such table: authtoken_token
"GET /admin/authtoken/tokenproxy/ HTTP/1.1" 500 195962
"GET /admin/ HTTP/1.1" 200 9910
"GET /admin/products/nfctag/ HTTP/1.1" 500 440134
Watching for file changes with StatReloader
C:\Users\Aleksey L\Desktop\kuzler\kuzler\products\models.py changed, reloading.
Watching for file changes with StatReloader
C:\Users\Aleksey L\Desktop\kuzler\kuzler\products\models.py changed, reloading.
Watching for file changes with StatReloader
Watching for file changes with StatReloader
"GET /admin/ HTTP/1.1" 200 9910
"GET /admin/products/nfctag/ HTTP/1.1" 500 440195
"GET /admin/ HTTP/1.1" 200 9910
Internal Server Error: /admin/products/product/
Traceback (most recent call last):
  File "C:\Users\Aleksey L\AppData\Local\Programs\Python\Python313\Lib\site-packages\django\db\backends\utils.py", line 105, in _execute
    return self.cursor.execute(sql, params)
           ~~~~~~~~~~~~~~~~~~~^^^^^^^^^^^^^
  File "C:\Users\Aleksey L\AppData\Local\Programs\Python\Python313\Lib\site-packages\django\db\backends\sqlite3\base.py", line 354, in execute
    return super().execute(query, params)
           ~~~~~~~~~~~~~~~^^^^^^^^^^^^^^^
sqlite3.OperationalError: no such column: products_product.created_at

The above exception was the direct cause of the following exception:

Traceback (most recent call last):
  File "C:\Users\Aleksey L\AppData\Local\Programs\Python\Python313\Lib\site-packages\django\core\handlers\exception.py", line 55, in inner
    response = get_response(request)
  File "C:\Users\Aleksey L\AppData\Local\Programs\Python\Python313\Lib\site-packages\django\core\handlers\base.py", line 197, in _get_response
    response = wrapped_callback(request, *callback_args, **callback_kwargs)
  File "C:\Users\Aleksey L\AppData\Local\Programs\Python\Python313\Lib\site-packages\django\contrib\admin\options.py", line 718, in wrapper
    return self.admin_site.admin_view(view)(*args, **kwargs)
           ~~~~~~~~~~~~~~~~~~~~~~~~~~~~~~~~^^^^^^^^^^^^^^^^^
  File "C:\Users\Aleksey L\AppData\Local\Programs\Python\Python313\Lib\site-packages\django\utils\decorators.py", line 188, in _view_wrapper
    result = _process_exception(request, e)
  File "C:\Users\Aleksey L\AppData\Local\Programs\Python\Python313\Lib\site-packages\django\utils\decorators.py", line 186, in _view_wrapper
    response = view_func(request, *args, **kwargs)
  File "C:\Users\Aleksey L\AppData\Local\Programs\Python\Python313\Lib\site-packages\django\views\decorators\cache.py", line 80, in _view_wrapper
    response = view_func(request, *args, **kwargs)
  File "C:\Users\Aleksey L\AppData\Local\Programs\Python\Python313\Lib\site-packages\django\contrib\admin\sites.py", line 241, in inner
    return view(request, *args, **kwargs)
  File "C:\Users\Aleksey L\AppData\Local\Programs\Python\Python313\Lib\site-packages\django\utils\decorators.py", line 48, in _wrapper
    return bound_method(*args, **kwargs)
  File "C:\Users\Aleksey L\AppData\Local\Programs\Python\Python313\Lib\site-packages\django\utils\decorators.py", line 188, in _view_wrapper
    result = _process_exception(request, e)
  File "C:\Users\Aleksey L\AppData\Local\Programs\Python\Python313\Lib\site-packages\django\utils\decorators.py", line 186, in _view_wrapper
    response = view_func(request, *args, **kwargs)
  File "C:\Users\Aleksey L\AppData\Local\Programs\Python\Python313\Lib\site-packages\django\contrib\admin\options.py", line 2140, in changelist_view
    "selection_note": _("0 of %(cnt)s selected") % {"cnt": len(cl.result_list)},
                                                           ~~~^^^^^^^^^^^^^^^^
  File "C:\Users\Aleksey L\AppData\Local\Programs\Python\Python313\Lib\site-packages\django\db\models\query.py", line 382, in __len__
    self._fetch_all()
    ~~~~~~~~~~~~~~~^^
  File "C:\Users\Aleksey L\AppData\Local\Programs\Python\Python313\Lib\site-packages\django\db\models\query.py", line 1928, in _fetch_all
    self._result_cache = list(self._iterable_class(self))
                         ~~~~^^^^^^^^^^^^^^^^^^^^^^^^^^^^
  File "C:\Users\Aleksey L\AppData\Local\Programs\Python\Python313\Lib\site-packages\django\db\models\query.py", line 91, in __iter__
    results = compiler.execute_sql(
        chunked_fetch=self.chunked_fetch, chunk_size=self.chunk_size
    )
  File "C:\Users\Aleksey L\AppData\Local\Programs\Python\Python313\Lib\site-packages\django\db\models\sql\compiler.py", line 1574, in execute_sql
    cursor.execute(sql, params)
    ~~~~~~~~~~~~~~^^^^^^^^^^^^^
  File "C:\Users\Aleksey L\AppData\Local\Programs\Python\Python313\Lib\site-packages\django\db\backends\utils.py", line 122, in execute
    return super().execute(sql, params)
           ~~~~~~~~~~~~~~~^^^^^^^^^^^^^
  File "C:\Users\Aleksey L\AppData\Local\Programs\Python\Python313\Lib\site-packages\django\db\backends\utils.py", line 79, in execute
    return self._execute_with_wrappers(
           ~~~~~~~~~~~~~~~~~~~~~~~~~~~^
        sql, params, many=False, executor=self._execute
        ^^^^^^^^^^^^^^^^^^^^^^^^^^^^^^^^^^^^^^^^^^^^^^^
    )
    ^
  File "C:\Users\Aleksey L\AppData\Local\Programs\Python\Python313\Lib\site-packages\django\db\backends\utils.py", line 92, in _execute_with_wrappers
    return executor(sql, params, many, context)
  File "C:\Users\Aleksey L\AppData\Local\Programs\Python\Python313\Lib\site-packages\django\db\backends\utils.py", line 100, in _execute
    with self.db.wrap_database_errors:
         ^^^^^^^^^^^^^^^^^^^^^^^^^^^^
  File "C:\Users\Aleksey L\AppData\Local\Programs\Python\Python313\Lib\site-packages\django\db\utils.py", line 91, in __exit__
    raise dj_exc_value.with_traceback(traceback) from exc_value
  File "C:\Users\Aleksey L\AppData\Local\Programs\Python\Python313\Lib\site-packages\django\db\backends\utils.py", line 105, in _execute
    return self.cursor.execute(sql, params)
           ~~~~~~~~~~~~~~~~~~~^^^^^^^^^^^^^
  File "C:\Users\Aleksey L\AppData\Local\Programs\Python\Python313\Lib\site-packages\django\db\backends\sqlite3\base.py", line 354, in execute
    return super().execute(query, params)
           ~~~~~~~~~~~~~~~^^^^^^^^^^^^^^^
django.db.utils.OperationalError: no such column: products_product.created_at
"GET /admin/products/product/ HTTP/1.1" 500 173606
"GET /admin/ HTTP/1.1" 200 9910
"GET /admin/products/nfctag/ HTTP/1.1" 500 440195
Watching for file changes with StatReloader
"GET /admin/products/ HTTP/1.1" 302 0
"GET /admin/login/?next=/admin/products/ HTTP/1.1" 200 4383
"POST /admin/login/?next=/admin/products/ HTTP/1.1" 200 4649
"POST /admin/login/?next=/admin/products/ HTTP/1.1" 200 4649
"POST /admin/login/?next=/admin/products/ HTTP/1.1" 200 4652
Watching for file changes with StatReloader
"GET /admin/ HTTP/1.1" 302 0
"GET /admin/login/?next=/admin/ HTTP/1.1" 200 4365
"POST /admin/login/?next=/admin/ HTTP/1.1" 302 0
"GET /admin/ HTTP/1.1" 200 8769
"GET /admin/products/nfctag/ HTTP/1.1" 200 9976
"GET /admin/jsi18n/ HTTP/1.1" 200 17546
"GET /admin/products/product/ HTTP/1.1" 200 11182
"GET /admin/jsi18n/ HTTP/1.1" 200 17546
"GET /admin/authtoken/tokenproxy/ HTTP/1.1" 200 10076
"GET /admin/products/product/ HTTP/1.1" 200 11182
"GET /admin/jsi18n/ HTTP/1.1" 200 17546
"GET /admin/products/product/add/ HTTP/1.1" 200 13798
"GET /admin/jsi18n/ HTTP/1.1" 200 17546
"GET /admin/products/nfctag/add/?_to_field=id&_popup=1 HTTP/1.1" 200 5190
"GET /admin/jsi18n/ HTTP/1.1" 200 17546
"POST /admin/products/nfctag/add/?_to_field=id&_popup=1 HTTP/1.1" 200 5411
"GET /admin/jsi18n/ HTTP/1.1" 200 17546
"POST /admin/products/nfctag/add/?_to_field=id&_popup=1 HTTP/1.1" 200 5527
"GET /admin/jsi18n/ HTTP/1.1" 200 17546
"POST /admin/products/nfctag/add/?_to_field=id&_popup=1 HTTP/1.1" 200 5609
"GET /admin/jsi18n/ HTTP/1.1" 200 17546
"GET /admin/products/nfctag/ HTTP/1.1" 200 9976
"GET /admin/jsi18n/ HTTP/1.1" 200 17546
"GET /admin/products/nfctag/add/ HTTP/1.1" 200 11197
"GET /admin/jsi18n/ HTTP/1.1" 200 17546
"POST /admin/products/nfctag/add/ HTTP/1.1" 200 11534
"GET /admin/jsi18n/ HTTP/1.1" 200 17546
"GET /admin/products/product/ HTTP/1.1" 200 11182
"GET /admin/jsi18n/ HTTP/1.1" 200 17546
"GET /admin/authtoken/tokenproxy/ HTTP/1.1" 200 10076
"GET /admin/products/nfctag/ HTTP/1.1" 200 9976
"GET /admin/jsi18n/ HTTP/1.1" 200 17546
"GET /admin/products/product/ HTTP/1.1" 200 11182
"GET /admin/jsi18n/ HTTP/1.1" 200 17546
"GET /admin/auth/user/ HTTP/1.1" 200 14164
"GET /admin/jsi18n/ HTTP/1.1" 200 17546
"GET /static/admin/img/sorting-icons.svg HTTP/1.1" 200 1097
"GET /admin/auth/user/add/ HTTP/1.1" 200 15059
"GET /admin/jsi18n/ HTTP/1.1" 200 17546
"POST /admin/auth/user/add/ HTTP/1.1" 200 15284
"GET /admin/jsi18n/ HTTP/1.1" 200 17546
"POST /admin/auth/user/add/ HTTP/1.1" 200 15324
"GET /admin/jsi18n/ HTTP/1.1" 200 17546
"GET /admin/auth/user/ HTTP/1.1" 200 14164
"GET /admin/jsi18n/ HTTP/1.1" 200 17546
"GET /admin/auth/user/add/ HTTP/1.1" 200 15059
"GET /admin/jsi18n/ HTTP/1.1" 200 17546
"POST /admin/auth/user/add/ HTTP/1.1" 200 15420
"GET /admin/jsi18n/ HTTP/1.1" 200 17546
"POST /admin/auth/user/add/ HTTP/1.1" 200 15324
"GET /admin/jsi18n/ HTTP/1.1" 200 17546
"POST /admin/auth/user/add/ HTTP/1.1" 302 0
"GET /admin/auth/user/2/change/ HTTP/1.1" 200 27053
"GET /admin/jsi18n/ HTTP/1.1" 200 17546
"GET /static/admin/js/calendar.js HTTP/1.1" 200 9141
"GET /static/admin/js/admin/DateTimeShortcuts.js HTTP/1.1" 200 19319
"GET /static/admin/img/icon-calendar.svg HTTP/1.1" 200 1086
"GET /static/admin/img/icon-clock.svg HTTP/1.1" 200 677
"GET /admin/auth/user/ HTTP/1.1" 200 14678
"GET /admin/jsi18n/ HTTP/1.1" 200 17546
"GET /static/admin/img/icon-no.svg HTTP/1.1" 200 560
"GET /admin/auth/user/add/ HTTP/1.1" 200 15059
"GET /admin/jsi18n/ HTTP/1.1" 200 17546
"POST /admin/auth/user/add/ HTTP/1.1" 302 0
"GET /admin/auth/user/3/change/ HTTP/1.1" 200 27043
"GET /admin/jsi18n/ HTTP/1.1" 200 17546
"GET /admin/auth/user/ HTTP/1.1" 200 15188
"GET /admin/jsi18n/ HTTP/1.1" 200 17546
"GET /admin/auth/user/?is_superuser__exact=1 HTTP/1.1" 200 14864
"GET /admin/jsi18n/ HTTP/1.1" 200 17546
"GET /admin/auth/user/? HTTP/1.1" 200 15188
"GET /admin/jsi18n/ HTTP/1.1" 200 17546
"GET /admin/auth/group/ HTTP/1.1" 200 9966
"GET /admin/jsi18n/ HTTP/1.1" 200 17546
"GET /admin/products/nfctag/ HTTP/1.1" 200 9976
"GET /admin/jsi18n/ HTTP/1.1" 200 17546
Watching for file changes with StatReloader
"GET /admin/ HTTP/1.1" 200 9536
